<?xml version="1.0"?>
<robot name="flexible_arm">
    <!-- Specify link material -->
    <material name="link_material">
        <!-- <color rgba="0.6 0.6 0.6 1.0"/> -->
        <color rgba="0.059 0.059 0.055 0.851"/>
    </material>

    <material name="goal_material">
        <color rgba="0.87 0.275 0.09 1.0"/>
    </material>

    <material name="wall_material">
        <color rgba="0.6 0.16 0.11 1.0"/>
    </material>

    <!-- world -->
    <link name="world"/>

    <!-- First link is a rigid link -->
    <link name="link1">
        <visual>
            <geometry>
                <cylinder radius="0.025" length="0.15"/>
            </geometry>
            <material name="link_material"/>
            <origin rpy="0 0 0" xyz ="0 0 0.075"/>
        </visual>
        <inertial>
            <origin xyz="0 0 0.12" rpy="0 0 0"/>
            <mass value="2" />
            <inertia ixx="0.0061" ixy="0.0" ixz="0.0" iyy="0.0061" iyz="0.0" izz="0.01125"/>
        </inertial>
    </link>

    <joint name="active_joint1" type="revolute">
        <parent link="world"/>
        <child link="link1"/>
        <axis xyz="0 0 1"/>
        <origin xyz="0 0 0" rpy="0 0 0"/>
        <limit effort="100.0" lower="-3.14159" upper="3.14159" velocity="3.14"/>
    </joint>

    <!-- flexible arm modeled using virtual link method -->
    <!-- Second link -->
    <link name="virtual_link2_1">
        <visual>
            <geometry>
                <box size="0.05 0.0075 0.05"/>
            </geometry>
            <material name="link_material"/>
            <origin rpy="0 0 0" xyz ="0.025 0 0"/>
        </visual>
        <inertial>
            <origin xyz="0.025 0 0" rpy="0 0 0"/>
            <mass value="0.03935" />
            <inertia ixx="8.21103333e-06" ixy="0" ixz="0" iyy="1.63958333e-05" iyz="0" izz="8.21103333e-06" />
        </inertial>
    </link>

    <joint name="active_joint2" type="revolute">
        <parent link="link1"/>
        <child link="virtual_link2_1"/>
        <axis xyz="0 0 1"/>
        <origin xyz="0 0 0.15" rpy="1.57 0 0"/>
        <limit effort="100.0" lower="-3.14159" upper="3.14159" velocity="3.14"/>
    </joint>

    <link name="virtual_link2_2">
        <visual>
            <geometry>
                <box size="0.1 0.0075 0.05"/>
            </geometry>
            <material name="link_material"/>
            <origin rpy="0 0 0" xyz ="0.05 0 0"/>
        </visual>
        <inertial>
            <origin xyz="0.05 0 0" rpy="0 0 0"/>
            <mass value="0.0787" />
            <inertia ixx="1.64220667e-05" ixy="0" ixz="0" iyy="8.19791667e-05" iyz="0" izz="6.56095667e-05" />
        </inertial>
    </link>

    <joint name="passive_joint1" type="revolute">
        <parent link="virtual_link2_1"/>
        <child link="virtual_link2_2"/>
        <axis xyz="0 0 1"/>
        <origin xyz="0.05 0 0" rpy="0 0 0"/>
        <limit effort="100.0" lower="-3.14159" upper="3.14159" velocity="3.14"/>
    </joint>

    <link name="virtual_link2_3">
        <visual>
            <geometry>
                <box size="0.1 0.0075 0.05"/>
            </geometry>
            <material name="link_material"/>
            <origin rpy="0 0 0" xyz ="0.05 0 0"/>
        </visual>
        <inertial>
            <origin xyz="0.05 0 0" rpy="0 0 0"/>
            <mass value="0.0787" />
            <inertia ixx="1.64220667e-05" ixy="0" ixz="0" iyy="8.19791667e-05" iyz="0" izz="6.56095667e-05" />
        </inertial>
    </link>

    <joint name="passive_joint2" type="revolute">
        <parent link="virtual_link2_2"/>
        <child link="virtual_link2_3"/>
        <axis xyz="0 0 1"/>
        <origin xyz="0.1 0 0" rpy="0 0 0"/>
        <limit effort="100.0" lower="-3.14159" upper="3.14159" velocity="3.14"/>
    </joint>

    <link name="virtual_link2_4">
        <visual>
            <geometry>
                <box size="0.1 0.0075 0.05"/>
            </geometry>
            <material name="link_material"/>
            <origin rpy="0 0 0" xyz ="0.05 0 0"/>
        </visual>
        <inertial>
            <origin xyz="0.05 0 0" rpy="0 0 0"/>
            <mass value="0.0787" />
            <inertia ixx="1.64220667e-05" ixy="0" ixz="0" iyy="8.19791667e-05" iyz="0" izz="6.56095667e-05" />
        </inertial>
    </link>

    <joint name="passive_joint3" type="revolute">
        <parent link="virtual_link2_3"/>
        <child link="virtual_link2_4"/>
        <axis xyz="0 0 1"/>
        <origin xyz="0.1 0 0" rpy="0 0 0"/>
        <limit effort="100.0" lower="-3.14159" upper="3.14159" velocity="3.14"/>
    </joint>

    <link name="virtual_link2_5">
        <visual>
            <geometry>
                <box size="0.1 0.0075 0.05"/>
            </geometry>
            <material name="link_material"/>
            <origin rpy="0 0 0" xyz ="0.05 0 0"/>
        </visual>
        <inertial>
            <origin xyz="0.05 0 0" rpy="0 0 0"/>
            <mass value="0.0787" />
            <inertia ixx="1.64220667e-05" ixy="0" ixz="0" iyy="8.19791667e-05" iyz="0" izz="6.56095667e-05" />
        </inertial>
    </link>

    <joint name="passive_joint4" type="revolute">
        <parent link="virtual_link2_4"/>
        <child link="virtual_link2_5"/>
        <axis xyz="0 0 1"/>
        <origin xyz="0.1 0 0" rpy="0 0 0"/>
        <limit effort="100.0" lower="-3.14159" upper="3.14159" velocity="3.14"/>
    </joint>

    <link name="virtual_link2_6">
    <visual>
        <geometry>
            <box size="0.05 0.0075 0.05"/>
        </geometry>
        <material name="link_material"/>
        <origin rpy="0 0 0" xyz ="0.025 0 0"/>
    </visual>
    <inertial>
        <origin xyz="0.025 0 0" rpy="0 0 0"/>
        <mass value="0.03935" />
        <inertia ixx="8.21103333e-06" ixy="0" ixz="0" iyy="1.63958333e-05" iyz="0" izz="8.21103333e-06" />
    </inertial>
    </link>

    <joint name="passive_joint5" type="revolute">
        <parent link="virtual_link2_5"/>
        <child link="virtual_link2_6"/>
        <axis xyz="0 0 1"/>
        <origin xyz="0.1 0 0" rpy="0 0 0"/>
        <limit effort="100.0" lower="-3.14159" upper="3.14159" velocity="3.14"/>
    </joint>

 
    <!--  -->
    <!-- Third link -->
    <link name="virtual_link3_1">
        <visual>
            <geometry>
                <box size="0.05 0.0075 0.05"/>
            </geometry>
            <material name="link_material"/>
            <origin rpy="0 0 0" xyz ="0.025 0 0"/>
        </visual>
        <inertial>
            <origin xyz="0.025 0 0" rpy="0 0 0"/>
            <mass value="0.03935" />
            <inertia ixx="8.21103333e-06" ixy="0" ixz="0" iyy="1.63958333e-05" iyz="0" izz="8.21103333e-06" />
        </inertial>
    </link>

    <joint name="active_joint3" type="revolute">
        <parent link="virtual_link2_6"/>
        <child link="virtual_link3_1"/>
        <axis xyz="0 0 1"/>
        <origin xyz="0.05 0 0" rpy="0 0 0"/>
        <limit effort="100.0" lower="-3.14159" upper="3.14159" velocity="3.14"/>
    </joint>

    <link name="virtual_link3_2">
        <visual>
            <geometry>
                <box size="0.1 0.0075 0.05"/>
            </geometry>
            <material name="link_material"/>
            <origin rpy="0 0 0" xyz ="0.05 0 0"/>
        </visual>
        <inertial>
            <origin xyz="0.05 0 0" rpy="0 0 0"/>
            <mass value="0.0787" />
            <inertia ixx="1.64220667e-05" ixy="0" ixz="0" iyy="8.19791667e-05" iyz="0" izz="6.56095667e-05" />
        </inertial>
    </link>

    <joint name="passive_joint3_1" type="revolute">
        <parent link="virtual_link3_1"/>
        <child link="virtual_link3_2"/>
        <axis xyz="0 0 1"/>
        <origin xyz="0.05 0 0" rpy="0 0 0"/>
        <limit effort="100.0" lower="-3.14159" upper="3.14159" velocity="3.14"/>
    </joint>

    <link name="virtual_link3_3">
        <visual>
            <geometry>
                <box size="0.1 0.0075 0.05"/>
            </geometry>
            <material name="link_material"/>
            <origin rpy="0 0 0" xyz ="0.05 0 0"/>
        </visual>
        <inertial>
            <origin xyz="0.05 0 0" rpy="0 0 0"/>
            <mass value="0.0787" />
            <inertia ixx="1.64220667e-05" ixy="0" ixz="0" iyy="8.19791667e-05" iyz="0" izz="6.56095667e-05" />
        </inertial>
    </link>

    <joint name="passive_joint3_2" type="revolute">
        <parent link="virtual_link3_2"/>
        <child link="virtual_link3_3"/>
        <axis xyz="0 0 1"/>
        <origin xyz="0.1 0 0" rpy="0 0 0"/>
        <limit effort="100.0" lower="-3.14159" upper="3.14159" velocity="3.14"/>
    </joint>

    <link name="virtual_link3_4">
        <visual>
            <geometry>
                <box size="0.1 0.0075 0.05"/>
            </geometry>
            <material name="link_material"/>
            <origin rpy="0 0 0" xyz ="0.05 0 0"/>
        </visual>
        <inertial>
            <origin xyz="0.05 0 0" rpy="0 0 0"/>
            <mass value="0.0787" />
            <inertia ixx="1.64220667e-05" ixy="0" ixz="0" iyy="8.19791667e-05" iyz="0" izz="6.56095667e-05" />
        </inertial>
    </link>

    <joint name="passive_joint3_3" type="revolute">
        <parent link="virtual_link3_3"/>
        <child link="virtual_link3_4"/>
        <axis xyz="0 0 1"/>
        <origin xyz="0.1 0 0" rpy="0 0 0"/>
        <limit effort="100.0" lower="-3.14159" upper="3.14159" velocity="3.14"/>
    </joint>

    <link name="virtual_link3_5">
        <visual>
            <geometry>
                <box size="0.1 0.0075 0.05"/>
            </geometry>
            <material name="link_material"/>
            <origin rpy="0 0 0" xyz ="0.05 0 0"/>
        </visual>
        <inertial>
            <origin xyz="0.05 0 0" rpy="0 0 0"/>
            <mass value="0.0787" />
            <inertia ixx="1.64220667e-05" ixy="0" ixz="0" iyy="8.19791667e-05" iyz="0" izz="6.56095667e-05" />
        </inertial>
    </link>

    <joint name="passive_joint3_4" type="revolute">
        <parent link="virtual_link3_4"/>
        <child link="virtual_link3_5"/>
        <axis xyz="0 0 1"/>
        <origin xyz="0.1 0 0" rpy="0 0 0"/>
        <limit effort="100.0" lower="-3.14159" upper="3.14159" velocity="3.14"/>
    </joint>

    <link name="virtual_link3_6">
    <visual>
        <geometry>
            <box size="0.05 0.0075 0.05"/>
        </geometry>
        <material name="link_material"/>
        <origin rpy="0 0 0" xyz ="0.025 0 0"/>
    </visual>
    <inertial>
        <origin xyz="0.025 0 0" rpy="0 0 0"/>
        <mass value="0.03935" />
        <inertia ixx="8.21103333e-06" ixy="0" ixz="0" iyy="1.63958333e-05" iyz="0" izz="8.21103333e-06" />
    </inertial>
    </link>

    <joint name="passive_joint3_5" type="revolute">
        <parent link="virtual_link3_5"/>
        <child link="virtual_link3_6"/>
        <axis xyz="0 0 1"/>
        <origin xyz="0.1 0 0" rpy="0 0 0"/>
        <limit effort="100.0" lower="-3.14159" upper="3.14159" velocity="3.14"/>
    </joint>


    <!-- Load or the end-effector -->
    <link name="load">
        <visual>
            <geometry>
                <sphere radius="0.025"/>
            </geometry>
            <material name="link_material"/>
            <origin rpy="0 0 0" xyz ="0 0 0"/>
        </visual>
        <inertial>
            <origin xyz="0.0125 0 0" rpy="0 0 0"/>
            <mass value="0" />
            <inertia ixx="0" ixy="0" ixz="0" iyy="0" iyz="0" izz="0" />
        </inertial>
  </link>

    <joint name="last_link_to_load" type="fixed">
        <parent link="virtual_link3_6"/>
        <child link="load"/>
        <axis xyz="0 0 1"/>
        <origin xyz="0.05 0 0" rpy="0 0 0"/>
    </joint>

    <!-- Goal/Target position -->
    <!-- <link name="goal">
        <visual>
            <geometry>
                <sphere radius="0.025"/>
            </geometry>
            <material name="goal_material"/>
            <origin rpy="0 0 0" xyz ="0 0 0"/>
        </visual>
        <inertial>
            <origin xyz="0.0125 0 0" rpy="0 0 0"/>
            <mass value="0" />
            <inertia ixx="0" ixy="0" ixz="0" iyy="0" iyz="0" izz="0" />
        </inertial>
    </link>
    
    <joint name="goal_link_to_world" type="floating">
        <parent link="world"/>
        <child link="goal"/>
        <origin xyz="0 0 0" rpy="0 0 0"/>
    </joint> -->

    <!-- Wall -->
    <!-- distance from origin to wall = -0.1 -->
    <!-- wall width = 2 -->
    <!-- wall height = 1 -->
    <!-- wall thickness = 0.075 -->
    <link name = "wall_link">
        <visual>
            <origin xyz="0 -0.0375 0.5" rpy="0 0 0" />
            <geometry>
                <box size="2 0.075 1"/>
            </geometry>
            <material name = "wall_material"/>
        </visual>
        <collision>
            <geometry>
                <box size="0.075 2 1"/>
            </geometry>
        </collision>
        <inertial>
            <mass value="15" />
            <inertia ixx="1.0" ixy="0.0" ixz="0.0" iyy="1.0" iyz="0.0" izz="1.0" />
        </inertial>
    </link>

    <joint name = "world_to_wall" type = "fixed">
        <parent link = "world" />
        <child link = "wall_link" />
        <origin xyz = "0 -0.15 0" />
    </joint>

</robot>
