<?xml version="1.0"?>
<robot name="flexible_arm">
    <!-- world -->
    <link name="world"/>

    <!-- First link is a rigid link -->
    <link name="link1">
        <visual>
            <geometry>
                <cylinder radius="0.025" length="0.15"/>
            </geometry>
            <origin rpy="0 0 0" xyz ="0 0 0.075"/>
        </visual>
        <inertial>
            <origin xyz="0 0 0.12" rpy="0 0 0"/>
            <mass value="2" />
            <inertia ixx="0.0061" ixy="0.0" ixz="0.0" iyy="0.0061" iyz="0.0" izz="0.01125"/>
        </inertial>
    </link>

    <joint name="active_joint1" type="revolute">
        <parent link="world"/>
        <child link="link1"/>
        <axis xyz="0 0 1"/>
        <origin xyz="0 0 0" rpy="0 0 0"/>
        <limit effort="100.0" lower="-3.14159" upper="3.14159" velocity="3.14"/>
    </joint>

    <!-- flexible arm modeled using virtual link method -->
    <!-- Second link -->
    <link name="virtual_link2_1">
        <visual>
            <geometry>
                <box size="0.025 0.025 0.01"/>
            </geometry>
            <origin rpy="0 0 0" xyz ="0.0125 0 0"/>
        </visual>
        <inertial>
            <origin xyz="0.0125 0 0" rpy="0 0 0"/>
            <mass value="0.019675" />
            <inertia ixx="0" ixy="0" ixz="0" iyy="0" iyz="0" izz="4.09895833e-06" />
        </inertial>
    </link>

    <joint name="active_joint2" type="revolute">
        <parent link="link1"/>
        <child link="virtual_link2_1"/>
        <axis xyz="0 0 1"/>
        <origin xyz="0 0 0.15" rpy="1.57 0 0"/>
        <limit effort="100.0" lower="-3.14159" upper="3.14159" velocity="3.14"/>
    </joint>

    <link name="virtual_link2_2">
        <visual>
            <geometry>
                <box size="0.05 0.025 0.01"/>
            </geometry>
            <origin rpy="0 0 0" xyz ="0.025 0 0"/>
        </visual>
        <inertial>
            <origin xyz="0.025 0 0" rpy="0 0 0"/>
            <mass value="0.03935" />
            <inertia ixx="0" ixy="0" ixz="0" iyy="0" iyz="0" izz="8.19791667e-06" />
        </inertial>
    </link>

    <joint name="passive_joint1" type="revolute">
        <parent link="virtual_link2_1"/>
        <child link="virtual_link2_2"/>
        <axis xyz="0 0 1"/>
        <origin xyz="0.025 0 0" rpy="0 0 0"/>
        <limit effort="100.0" lower="-3.14159" upper="3.14159" velocity="3.14"/>
    </joint>

    <link name="virtual_link2_3">
        <visual>
            <geometry>
                <box size="0.05 0.025 0.01"/>
            </geometry>
            <origin rpy="0 0 0" xyz ="0.025 0 0"/>
        </visual>
        <inertial>
            <origin xyz="0.025 0 0" rpy="0 0 0"/>
            <mass value="0.03935" />
            <inertia ixx="0" ixy="0" ixz="0" iyy="0" iyz="0" izz="8.19791667e-06" />
        </inertial>
    </link>

    <joint name="passive_joint2" type="revolute">
        <parent link="virtual_link2_2"/>
        <child link="virtual_link2_3"/>
        <axis xyz="0 0 1"/>
        <origin xyz="0.05 0 0" rpy="0 0 0"/>
        <limit effort="100.0" lower="-3.14159" upper="3.14159" velocity="3.14"/>
    </joint>

    <link name="virtual_link2_4">
        <visual>
            <geometry>
                <box size="0.05 0.025 0.01"/>
            </geometry>
            <origin rpy="0 0 0" xyz ="0.025 0 0"/>
        </visual>
        <inertial>
            <origin xyz="0.025 0 0" rpy="0 0 0"/>
            <mass value="0.03935" />
            <inertia ixx="0" ixy="0" ixz="0" iyy="0" iyz="0" izz="8.19791667e-06" />
        </inertial>
    </link>

    <joint name="passive_joint3" type="revolute">
        <parent link="virtual_link2_3"/>
        <child link="virtual_link2_4"/>
        <axis xyz="0 0 1"/>
        <origin xyz="0.05 0 0" rpy="0 0 0"/>
        <limit effort="100.0" lower="-3.14159" upper="3.14159" velocity="3.14"/>
    </joint>

    <link name="virtual_link2_5">
        <visual>
            <geometry>
                <box size="0.05 0.025 0.01"/>
            </geometry>
            <origin rpy="0 0 0" xyz ="0.025 0 0"/>
        </visual>
        <inertial>
            <origin xyz="0.025 0 0" rpy="0 0 0"/>
            <mass value="0.03935" />
            <inertia ixx="0" ixy="0" ixz="0" iyy="0" iyz="0" izz="8.19791667e-06" />
        </inertial>
    </link>

    <joint name="passive_joint4" type="revolute">
        <parent link="virtual_link2_4"/>
        <child link="virtual_link2_5"/>
        <axis xyz="0 0 1"/>
        <origin xyz="0.05 0 0" rpy="0 0 0"/>
        <limit effort="100.0" lower="-3.14159" upper="3.14159" velocity="3.14"/>
    </joint>

    <link name="virtual_link2_6">
    <visual>
        <geometry>
            <box size="0.05 0.025 0.01"/>
        </geometry>
        <origin rpy="0 0 0" xyz ="0.025 0 0"/>
    </visual>
    <inertial>
        <origin xyz="0.025 0 0" rpy="0 0 0"/>
        <mass value="0.03935" />
        <inertia ixx="0" ixy="0" ixz="0" iyy="0" iyz="0" izz="8.19791667e-06" />
    </inertial>
    </link>

    <joint name="passive_joint5" type="revolute">
        <parent link="virtual_link2_5"/>
        <child link="virtual_link2_6"/>
        <axis xyz="0 0 1"/>
        <origin xyz="0.05 0 0" rpy="0 0 0"/>
        <limit effort="100.0" lower="-3.14159" upper="3.14159" velocity="3.14"/>
    </joint>

    <link name="virtual_link2_7">
        <visual>
            <geometry>
                <box size="0.05 0.025 0.01"/>
            </geometry>
            <origin rpy="0 0 0" xyz ="0.025 0 0"/>
        </visual>
        <inertial>
            <origin xyz="0.025 0 0" rpy="0 0 0"/>
            <mass value="0.03935" />
            <inertia ixx="0" ixy="0" ixz="0" iyy="0" iyz="0" izz="8.19791667e-06" />
        </inertial>
    </link>

    <joint name="passive_joint6" type="revolute">
        <parent link="virtual_link2_6"/>
        <child link="virtual_link2_7"/>
        <axis xyz="0 0 1"/>
        <origin xyz="0.05 0 0" rpy="0 0 0"/>
        <limit effort="100.0" lower="-3.14159" upper="3.14159" velocity="3.14"/>
    </joint>

    <link name="virtual_link2_8">
        <visual>
            <geometry>
                <box size="0.05 0.025 0.01"/>
            </geometry>
            <origin rpy="0 0 0" xyz ="0.025 0 0"/>
        </visual>
        <inertial>
            <origin xyz="0.025 0 0" rpy="0 0 0"/>
            <mass value="0.03935" />
            <inertia ixx="0" ixy="0" ixz="0" iyy="0" iyz="0" izz="8.19791667e-06" />
        </inertial>
    </link>

    <joint name="passive_joint7" type="revolute">
        <parent link="virtual_link2_7"/>
        <child link="virtual_link2_8"/>
        <axis xyz="0 0 1"/>
        <origin xyz="0.05 0 0" rpy="0 0 0"/>
        <limit effort="100.0" lower="-3.14159" upper="3.14159" velocity="3.14"/>
    </joint>

    <link name="virtual_link2_9">
        <visual>
            <geometry>
                <box size="0.05 0.025 0.01"/>
            </geometry>
            <origin rpy="0 0 0" xyz ="0.025 0 0"/>
        </visual>
        <inertial>
            <origin xyz="0.025 0 0" rpy="0 0 0"/>
            <mass value="0.03935" />
            <inertia ixx="0" ixy="0" ixz="0" iyy="0" iyz="0" izz="8.19791667e-06" />
        </inertial>
    </link>

    <joint name="passive_joint8" type="revolute">
        <parent link="virtual_link2_8"/>
        <child link="virtual_link2_9"/>
        <axis xyz="0 0 1"/>
        <origin xyz="0.05 0 0" rpy="0 0 0"/>
        <limit effort="100.0" lower="-3.14159" upper="3.14159" velocity="3.14"/>
    </joint>

    <link name="virtual_link2_10">
        <visual>
            <geometry>
                <box size="0.05 0.025 0.01"/>
            </geometry>
            <origin rpy="0 0 0" xyz ="0.025 0 0"/>
        </visual>
        <inertial>
            <origin xyz="0.025 0 0" rpy="0 0 0"/>
            <mass value="0.03935" />
            <inertia ixx="0" ixy="0" ixz="0" iyy="0" iyz="0" izz="8.19791667e-06" />
        </inertial>
    </link>

    <joint name="passive_joint9" type="revolute">
        <parent link="virtual_link2_9"/>
        <child link="virtual_link2_10"/>
        <axis xyz="0 0 1"/>
        <origin xyz="0.05 0 0" rpy="0 0 0"/>
        <limit effort="100.0" lower="-3.14159" upper="3.14159" velocity="3.14"/>
    </joint>

    <link name="virtual_link2_11">
        <visual>
            <geometry>
                <box size="0.025 0.025 0.01"/>
            </geometry>
            <origin rpy="0 0 0" xyz ="0.0125 0 0"/>
        </visual>
        <inertial>
            <origin xyz="0.0125 0 0" rpy="0 0 0"/>
            <mass value="0.019675" />
            <inertia ixx="0" ixy="0" ixz="0" iyy="0" iyz="0" izz="4.09895833e-06" />
        </inertial>
    </link>

    <joint name="passive_joint10" type="revolute">
        <parent link="virtual_link2_10"/>
        <child link="virtual_link2_11"/>
        <axis xyz="0 0 1"/>
        <origin xyz="0.05 0 0" rpy="0 0 0"/>
        <limit effort="100.0" lower="-3.14159" upper="3.14159" velocity="3.14"/>
    </joint>

 
    <!--  -->
    <!-- Third link -->
    <link name="virtual_link3_1">
        <visual>
            <geometry>
                <box size="0.025 0.025 0.01"/>
            </geometry>
            <origin rpy="0 0 0" xyz ="0.0125 0 0"/>
        </visual>
        <inertial>
            <origin xyz="0.0125 0 0" rpy="0 0 0"/>
            <mass value="0.019675" />
            <inertia ixx="0" ixy="0" ixz="0" iyy="0" iyz="0" izz="4.09895833e-06" />
        </inertial>
    </link>

    <joint name="active_joint3" type="revolute">
        <parent link="virtual_link2_11"/>
        <child link="virtual_link3_1"/>
        <axis xyz="0 0 1"/>
        <origin xyz="0.025 0 0" rpy="0 0 0"/>
        <limit effort="100.0" lower="-3.14159" upper="3.14159" velocity="3.14"/>
    </joint>

    <link name="virtual_link3_2">
        <visual>
            <geometry>
                <box size="0.05 0.025 0.01"/>
            </geometry>
            <origin rpy="0 0 0" xyz ="0.025 0 0"/>
        </visual>
        <inertial>
            <origin xyz="0.025 0 0" rpy="0 0 0"/>
            <mass value="0.03935" />
            <inertia ixx="0" ixy="0" ixz="0" iyy="0" iyz="0" izz="8.19791667e-06" />
        </inertial>
    </link>

    <joint name="passive_joint3_1" type="revolute">
        <parent link="virtual_link3_1"/>
        <child link="virtual_link3_2"/>
        <axis xyz="0 0 1"/>
        <origin xyz="0.025 0 0" rpy="0 0 0"/>
        <limit effort="100.0" lower="-3.14159" upper="3.14159" velocity="3.14"/>
    </joint>

    <link name="virtual_link3_3">
        <visual>
            <geometry>
                <box size="0.05 0.025 0.01"/>
            </geometry>
            <origin rpy="0 0 0" xyz ="0.025 0 0"/>
        </visual>
        <inertial>
            <origin xyz="0.025 0 0" rpy="0 0 0"/>
            <mass value="0.03935" />
            <inertia ixx="0" ixy="0" ixz="0" iyy="0" iyz="0" izz="8.19791667e-06" />
        </inertial>
    </link>

    <joint name="passive_joint3_2" type="revolute">
        <parent link="virtual_link3_2"/>
        <child link="virtual_link3_3"/>
        <axis xyz="0 0 1"/>
        <origin xyz="0.05 0 0" rpy="0 0 0"/>
        <limit effort="100.0" lower="-3.14159" upper="3.14159" velocity="3.14"/>
    </joint>

    <link name="virtual_link3_4">
        <visual>
            <geometry>
                <box size="0.05 0.025 0.01"/>
            </geometry>
            <origin rpy="0 0 0" xyz ="0.025 0 0"/>
        </visual>
        <inertial>
            <origin xyz="0.025 0 0" rpy="0 0 0"/>
            <mass value="0.03935" />
            <inertia ixx="0" ixy="0" ixz="0" iyy="0" iyz="0" izz="8.19791667e-06" />
        </inertial>
    </link>

    <joint name="passive_joint3_3" type="revolute">
        <parent link="virtual_link3_3"/>
        <child link="virtual_link3_4"/>
        <axis xyz="0 0 1"/>
        <origin xyz="0.05 0 0" rpy="0 0 0"/>
        <limit effort="100.0" lower="-3.14159" upper="3.14159" velocity="3.14"/>
    </joint>

    <link name="virtual_link3_5">
        <visual>
            <geometry>
                <box size="0.05 0.025 0.01"/>
            </geometry>
            <origin rpy="0 0 0" xyz ="0.025 0 0"/>
        </visual>
        <inertial>
            <origin xyz="0.025 0 0" rpy="0 0 0"/>
            <mass value="0.03935" />
            <inertia ixx="0" ixy="0" ixz="0" iyy="0" iyz="0" izz="8.19791667e-06" />
        </inertial>
    </link>

    <joint name="passive_joint3_4" type="revolute">
        <parent link="virtual_link3_4"/>
        <child link="virtual_link3_5"/>
        <axis xyz="0 0 1"/>
        <origin xyz="0.05 0 0" rpy="0 0 0"/>
        <limit effort="100.0" lower="-3.14159" upper="3.14159" velocity="3.14"/>
    </joint>

    <link name="virtual_link3_6">
    <visual>
        <geometry>
            <box size="0.05 0.025 0.01"/>
        </geometry>
        <origin rpy="0 0 0" xyz ="0.025 0 0"/>
    </visual>
    <inertial>
        <origin xyz="0.025 0 0" rpy="0 0 0"/>
        <mass value="0.03935" />
        <inertia ixx="0" ixy="0" ixz="0" iyy="0" iyz="0" izz="8.19791667e-06" />
    </inertial>
    </link>

    <joint name="passive_joint3_5" type="revolute">
        <parent link="virtual_link3_5"/>
        <child link="virtual_link3_6"/>
        <axis xyz="0 0 1"/>
        <origin xyz="0.05 0 0" rpy="0 0 0"/>
        <limit effort="100.0" lower="-3.14159" upper="3.14159" velocity="3.14"/>
    </joint>

    <link name="virtual_link3_7">
        <visual>
            <geometry>
                <box size="0.05 0.025 0.01"/>
            </geometry>
            <origin rpy="0 0 0" xyz ="0.025 0 0"/>
        </visual>
        <inertial>
            <origin xyz="0.025 0 0" rpy="0 0 0"/>
            <mass value="0.03935" />
            <inertia ixx="0" ixy="0" ixz="0" iyy="0" iyz="0" izz="8.19791667e-06" />
        </inertial>
    </link>

    <joint name="passive_joint3_6" type="revolute">
        <parent link="virtual_link3_6"/>
        <child link="virtual_link3_7"/>
        <axis xyz="0 0 1"/>
        <origin xyz="0.05 0 0" rpy="0 0 0"/>
        <limit effort="100.0" lower="-3.14159" upper="3.14159" velocity="3.14"/>
    </joint>

    <link name="virtual_link3_8">
        <visual>
            <geometry>
                <box size="0.05 0.025 0.01"/>
            </geometry>
            <origin rpy="0 0 0" xyz ="0.025 0 0"/>
        </visual>
        <inertial>
            <origin xyz="0.025 0 0" rpy="0 0 0"/>
            <mass value="0.03935" />
            <inertia ixx="0" ixy="0" ixz="0" iyy="0" iyz="0" izz="8.19791667e-06" />
        </inertial>
    </link>

    <joint name="passive_joint3_7" type="revolute">
        <parent link="virtual_link3_7"/>
        <child link="virtual_link3_8"/>
        <axis xyz="0 0 1"/>
        <origin xyz="0.05 0 0" rpy="0 0 0"/>
        <limit effort="100.0" lower="-3.14159" upper="3.14159" velocity="3.14"/>
    </joint>

    <link name="virtual_link3_9">
        <visual>
            <geometry>
                <box size="0.05 0.025 0.01"/>
            </geometry>
            <origin rpy="0 0 0" xyz ="0.025 0 0"/>
        </visual>
        <inertial>
            <origin xyz="0.025 0 0" rpy="0 0 0"/>
            <mass value="0.03935" />
            <inertia ixx="0" ixy="0" ixz="0" iyy="0" iyz="0" izz="8.19791667e-06" />
        </inertial>
    </link>

    <joint name="passive_joint3_8" type="revolute">
        <parent link="virtual_link3_8"/>
        <child link="virtual_link3_9"/>
        <axis xyz="0 0 1"/>
        <origin xyz="0.05 0 0" rpy="0 0 0"/>
        <limit effort="100.0" lower="-3.14159" upper="3.14159" velocity="3.14"/>
    </joint>

    <link name="virtual_link3_10">
        <visual>
            <geometry>
                <box size="0.05 0.025 0.01"/>
            </geometry>
            <origin rpy="0 0 0" xyz ="0.025 0 0"/>
        </visual>
        <inertial>
            <origin xyz="0.025 0 0" rpy="0 0 0"/>
            <mass value="0.03935" />
            <inertia ixx="0" ixy="0" ixz="0" iyy="0" iyz="0" izz="8.19791667e-06" />
        </inertial>
    </link>

    <joint name="passive_joint3_9" type="revolute">
        <parent link="virtual_link3_9"/>
        <child link="virtual_link3_10"/>
        <axis xyz="0 0 1"/>
        <origin xyz="0.05 0 0" rpy="0 0 0"/>
        <limit effort="100.0" lower="-3.14159" upper="3.14159" velocity="3.14"/>
    </joint>

    <link name="virtual_link3_11">
        <visual>
            <geometry>
                <box size="0.025 0.025 0.01"/>
            </geometry>
            <origin rpy="0 0 0" xyz ="0.0125 0 0"/>
        </visual>
        <inertial>
            <origin xyz="0.0125 0 0" rpy="0 0 0"/>
            <mass value="0.019675" />
            <inertia ixx="0" ixy="0" ixz="0" iyy="0" iyz="0" izz="4.09895833e-06" />
        </inertial>
    </link>

    <joint name="passive_joint3_10" type="revolute">
        <parent link="virtual_link3_10"/>
        <child link="virtual_link3_11"/>
        <axis xyz="0 0 1"/>
        <origin xyz="0.05 0 0" rpy="0 0 0"/>
        <limit effort="100.0" lower="-3.14159" upper="3.14159" velocity="3.14"/>
    </joint>

    <link name="load">
        <visual>
            <geometry>
                <sphere radius="0.05"/>
            </geometry>
            <origin rpy="0 0 0" xyz ="0.05 0 0"/>
        </visual>
        <inertial>
            <origin xyz="0.025 0 0" rpy="0 0 0"/>
            <mass value="0" />
            <inertia ixx="0" ixy="0" ixz="0" iyy="0" iyz="0" izz="0" />
        </inertial>
  </link>

    <joint name="last_link_to_load" type="fixed">
        <parent link="virtual_link3_11"/>
        <child link="load"/>
        <axis xyz="0 0 1"/>
        <origin xyz="0.025 0 0" rpy="0 0 0"/>
    </joint>
</robot>
