<mujoco model="flexible_arm">
  <compiler angle="radian"/>
  <option timestep="0.001" integrator="implicit"/>

  <visual>
    <global azimuth="45" elevation="-15"/>
    <headlight ambient="0.3 0.3 0.3" diffuse="0.6 0.6 0.6" specular="0 0 0"/>
    <rgba haze="0.15 0.25 0.35 1"/>
  </visual>  

  <statistic meansize="0.0269565" extent="2.23733" center="0 0 0"/>
  
   <asset>
    <texture type="skybox" builtin="gradient" rgb1="0.3 0.5 0.7" 
        rgb2="0 0 0" width="512" height="3072"/>
    <texture type="2d" name="groundplane" builtin="checker" mark="edge" rgb1="0.2 0.3 0.4" 
        rgb2="0.1 0.2 0.3" markrgb="0.8 0.8 0.8" width="300" height="300"/>
    <material name="groundplane" texture="groundplane" texuniform="true" 
        texrepeat="5 5" reflectance="0.2"/>
    <material name="dark_grey" rgba="0.25 0.25 0.25 1"/>
   </asset>
  

  <worldbody>
    <geom name="floor" type="plane" pos="0 0 0" size="0 0 0.05" material="groundplane"/>
    <light pos="0 0 1.5" dir="0 0 -1" directional="true"/>

    <!-- <geom size="1 0.0375 0.5" pos="0 -0.15 0.5" type="box" rgba="0.6 0.16 0.11 1"/> -->
    <body name="link1">
      <inertial pos="0 0 0.12" quat="0.5 0.5 -0.5 0.5" mass="2" diaginertia="0.01125 0.0061 0.0061"/>
      <joint name="active_joint1" pos="0 0 0" axis="0 0 1" range="-3.14159 3.14159"/>
      <geom size="0.035 0.075" pos="0 0 0.075" type="cylinder" material="dark_grey"/>
      
      <body name="virtual_link2_1" pos="0 0 0.15" quat="0.707388 0.706825 0 0">
        <inertial pos="0.0125 0 0" quat="0.707107 0 0 0.707107" mass="0.019675" diaginertia="5.1237e-06 4.10552e-06 1.0313e-06"/>
        <joint name="active_joint2" pos="0 0 0" axis="0 0 1" range="-3.14159 3.14159"/>
        <!-- <geom size="0.0125 0.0075 0.025" pos="0.0125 0 0" type="box" material="dark_grey"/> -->
        <geom size="0.015 0.025" pos="0.0125 0 0" type="capsule" material="dark_grey"/>
        <body name="virtual_link2_2" pos="0.025 0 0">
          <inertial pos="0.025 0 0" quat="0.707107 0 0 0.707107" mass="0.03935" diaginertia="1.63958e-05 8.21103e-06 8.21103e-06"/>
          <joint name="passive_joint1" pos="0 0 0" axis="0 0 1" stiffness="30" damping="0.5674" range="-3.14159 3.14159"/>
          <geom size="0.025 0.0075 0.025" pos="0.025 0 0" type="box" material="dark_grey"/>
          <body name="virtual_link2_3" pos="0.05 0 0">
            <inertial pos="0.025 0 0" quat="0.707107 0 0 0.707107" mass="0.03935" diaginertia="1.63958e-05 8.21103e-06 8.21103e-06"/>
            <joint name="passive_joint2" pos="0 0 0" axis="0 0 1" stiffness="30" damping="0.5674" range="-3.14159 3.14159"/>
            <geom size="0.025 0.0075 0.025" pos="0.025 0 0" type="box" material="dark_grey"/>
            <body name="virtual_link2_4" pos="0.05 0 0">
              <inertial pos="0.025 0 0" quat="0.707107 0 0 0.707107" mass="0.03935" diaginertia="1.63958e-05 8.21103e-06 8.21103e-06"/>
              <joint name="passive_joint3" pos="0 0 0" axis="0 0 1" stiffness="30" damping="0.5674" range="-3.14159 3.14159"/>
              <geom size="0.025 0.0075 0.025" pos="0.025 0 0" type="box" material="dark_grey"/>
              <body name="virtual_link2_5" pos="0.05 0 0">
                <inertial pos="0.025 0 0" quat="0.707107 0 0 0.707107" mass="0.03935" diaginertia="1.63958e-05 8.21103e-06 8.21103e-06"/>
                <joint name="passive_joint4" pos="0 0 0" axis="0 0 1" stiffness="30" damping="0.5674" range="-3.14159 3.14159"/>
                <geom size="0.025 0.0075 0.025" pos="0.025 0 0" type="box" material="dark_grey"/>
                <body name="virtual_link2_6" pos="0.05 0 0">
                  <inertial pos="0.025 0 0" quat="0.707107 0 0 0.707107" mass="0.03935" diaginertia="1.63958e-05 8.21103e-06 8.21103e-06"/>
                  <joint name="passive_joint5" pos="0 0 0" axis="0 0 1" stiffness="30" damping="0.5674" range="-3.14159 3.14159"/>
                  <geom size="0.025 0.0075 0.025" pos="0.025 0 0" type="box" material="dark_grey"/>
                  <body name="virtual_link2_7" pos="0.05 0 0">
                    <inertial pos="0.025 0 0" quat="0.707107 0 0 0.707107" mass="0.03935" diaginertia="1.63958e-05 8.21103e-06 8.21103e-06"/>
                    <joint name="passive_joint6" pos="0 0 0" axis="0 0 1" stiffness="30" damping="0.5674" range="-3.14159 3.14159"/>
                    <geom size="0.025 0.0075 0.025" pos="0.025 0 0" type="box" material="dark_grey"/>
                    <body name="virtual_link2_8" pos="0.05 0 0">
                      <inertial pos="0.025 0 0" quat="0.707107 0 0 0.707107" mass="0.03935" diaginertia="1.63958e-05 8.21103e-06 8.21103e-06"/>
                      <joint name="passive_joint7" pos="0 0 0" axis="0 0 1" stiffness="30" damping="0.5674" range="-3.14159 3.14159"/>
                      <geom size="0.025 0.0075 0.025" pos="0.025 0 0" type="box" material="dark_grey"/>
                      <body name="virtual_link2_9" pos="0.05 0 0">
                        <inertial pos="0.025 0 0" quat="0.707107 0 0 0.707107" mass="0.03935" diaginertia="1.63958e-05 8.21103e-06 8.21103e-06"/>
                        <joint name="passive_joint8" pos="0 0 0" axis="0 0 1" stiffness="30" damping="0.5674" range="-3.14159 3.14159"/>
                        <geom size="0.025 0.0075 0.025" pos="0.025 0 0" type="box" material="dark_grey"/>
                        <body name="virtual_link2_10" pos="0.05 0 0">
                          <inertial pos="0.025 0 0" quat="0.707107 0 0 0.707107" mass="0.03935" diaginertia="1.63958e-05 8.21103e-06 8.21103e-06"/>
                          <joint name="passive_joint9" pos="0 0 0" axis="0 0 1" stiffness="30" damping="0.5674" range="-3.14159 3.14159"/>
                          <geom size="0.025 0.0075 0.025" pos="0.025 0 0" type="box" material="dark_grey"/>
                          <body name="virtual_link2_11" pos="0.05 0 0">
                            <inertial pos="0.0125 0 0" quat="0.707107 0 0 0.707107" mass="0.019675" diaginertia="5.1237e-06 4.10552e-06 1.0313e-06"/>
                            <joint name="passive_joint10" pos="0 0 0" axis="0 0 1" stiffness="30" damping="0.5674" range="-3.14159 3.14159"/>
                            <geom size="0.0125 0.0075 0.025" pos="0.0125 0 0" type="box" material="dark_grey"/>
                            
                            <body name="virtual_link3_1" pos="0.025 0 0">
                              <inertial pos="0.0125 0 0" quat="0.707107 0 0 0.707107" mass="0.019675" diaginertia="5.1237e-06 4.10552e-06 1.0313e-06"/>
                              <joint name="active_joint3" pos="0 0 0" axis="0 0 1" range="-3.14159 3.14159"/>
                              <!-- <geom size="0.0125 0.0075 0.025" pos="0.0125 0 0" type="box" material="dark_grey"/> -->
                              <geom size="0.015 0.025" pos="0.0125 0 0" type="capsule" material="dark_grey"/>
                              <body name="virtual_link3_2" pos="0.025 0 0">
                                <inertial pos="0.025 0 0" quat="0.707107 0 0 0.707107" mass="0.03935" diaginertia="1.63958e-05 8.21103e-06 8.21103e-06"/>
                                <joint name="passive_joint3_1" pos="0 0 0" axis="0 0 1" stiffness="30" damping="0.5674" range="-3.14159 3.14159"/>
                                <geom size="0.025 0.0075 0.025" pos="0.025 0 0" type="box" material="dark_grey"/>
                                <body name="virtual_link3_3" pos="0.05 0 0">
                                  <inertial pos="0.025 0 0" quat="0.707107 0 0 0.707107" mass="0.03935" diaginertia="1.63958e-05 8.21103e-06 8.21103e-06"/>
                                  <joint name="passive_joint3_2" pos="0 0 0" axis="0 0 1" stiffness="30" damping="0.5674" range="-3.14159 3.14159"/>
                                  <geom size="0.025 0.0075 0.025" pos="0.025 0 0" type="box" material="dark_grey"/>
                                  <body name="virtual_link3_4" pos="0.05 0 0">
                                    <inertial pos="0.025 0 0" quat="0.707107 0 0 0.707107" mass="0.03935" diaginertia="1.63958e-05 8.21103e-06 8.21103e-06"/>
                                    <joint name="passive_joint3_3" pos="0 0 0" axis="0 0 1" stiffness="30" damping="0.5674" range="-3.14159 3.14159"/>
                                    <geom size="0.025 0.0075 0.025" pos="0.025 0 0" type="box" material="dark_grey"/>
                                    <body name="virtual_link3_5" pos="0.05 0 0">
                                      <inertial pos="0.025 0 0" quat="0.707107 0 0 0.707107" mass="0.03935" diaginertia="1.63958e-05 8.21103e-06 8.21103e-06"/>
                                      <joint name="passive_joint3_4" pos="0 0 0" axis="0 0 1" stiffness="30" damping="0.5674" range="-3.14159 3.14159"/>
                                      <geom size="0.025 0.0075 0.025" pos="0.025 0 0" type="box" material="dark_grey"/>
                                      <body name="virtual_link3_6" pos="0.05 0 0">
                                        <inertial pos="0.025 0 0" quat="0.707107 0 0 0.707107" mass="0.03935" diaginertia="1.63958e-05 8.21103e-06 8.21103e-06"/>
                                        <joint name="passive_joint3_5" pos="0 0 0" axis="0 0 1" stiffness="30" damping="0.5674" range="-3.14159 3.14159"/>
                                        <geom size="0.025 0.0075 0.025" pos="0.025 0 0" type="box" material="dark_grey"/>
                                        <body name="virtual_link3_7" pos="0.05 0 0">
                                          <inertial pos="0.025 0 0" quat="0.707107 0 0 0.707107" mass="0.03935" diaginertia="1.63958e-05 8.21103e-06 8.21103e-06"/>
                                          <joint name="passive_joint3_6" pos="0 0 0" axis="0 0 1" stiffness="30" damping="0.5674" range="-3.14159 3.14159"/>
                                          <geom size="0.025 0.0075 0.025" pos="0.025 0 0" type="box" material="dark_grey"/>
                                          <body name="virtual_link3_8" pos="0.05 0 0">
                                            <inertial pos="0.025 0 0" quat="0.707107 0 0 0.707107" mass="0.03935" diaginertia="1.63958e-05 8.21103e-06 8.21103e-06"/>
                                            <joint name="passive_joint3_7" pos="0 0 0" axis="0 0 1" stiffness="30" damping="0.5674" range="-3.14159 3.14159"/>
                                            <geom size="0.025 0.0075 0.025" pos="0.025 0 0" type="box" material="dark_grey"/>
                                            <body name="virtual_link3_9" pos="0.05 0 0">
                                              <inertial pos="0.025 0 0" quat="0.707107 0 0 0.707107" mass="0.03935" diaginertia="1.63958e-05 8.21103e-06 8.21103e-06"/>
                                              <joint name="passive_joint3_8" pos="0 0 0" axis="0 0 1" stiffness="30" damping="0.5674" range="-3.14159 3.14159"/>
                                              <geom size="0.025 0.0075 0.025" pos="0.025 0 0" type="box" material="dark_grey"/>
                                              <body name="virtual_link3_10" pos="0.05 0 0">
                                                <inertial pos="0.025 0 0" quat="0.707107 0 0 0.707107" mass="0.03935" diaginertia="1.63958e-05 8.21103e-06 8.21103e-06"/>
                                                <joint name="passive_joint3_9" pos="0 0 0" axis="0 0 1" stiffness="30" damping="0.5674" range="-3.14159 3.14159"/>
                                                <geom size="0.025 0.0075 0.025" pos="0.025 0 0" type="box" material="dark_grey"/>
                                                <body name="virtual_link3_11" pos="0.05 0 0">
                                                  <inertial pos="0.0125 0 0" quat="0.707107 0 0 0.707107" mass="0.019675" diaginertia="5.1237e-06 4.10552e-06 1.0313e-06"/>
                                                  <joint name="passive_joint3_10" pos="0 0 0" axis="0 0 1" stiffness="30" damping="0.5674" range="-3.14159 3.14159"/>
                                                  <geom size="0.0125 0.0075 0.025" pos="0.0125 0 0" type="box" material="dark_grey"/>
                                                </body>
                                              </body>
                                            </body>
                                          </body>
                                        </body>
                                      </body>
                                    </body>
                                  </body>
                                </body>
                              </body>
                            </body>
                          </body>
                        </body>
                      </body>
                    </body>
                  </body>
                </body>
              </body>
            </body>
          </body>
        </body>
      </body>
    </body>
  </worldbody>
  <actuator>
    <motor name="actuator1" joint="active_joint1" />
    <motor name="actuator2" joint="active_joint2" />
    <motor name="actuator3" joint="active_joint3" />
  </actuator>

</mujoco>
